INFO:sentence_transformers.SentenceTransformer:Load pretrained SentenceTransformer: facebook-dpr-ctx_encoder-multiset-base
INFO:sentence_transformers.SentenceTransformer:Use pytorch device: cpu
INFO:sentence_transformers.SentenceTransformer:Load pretrained SentenceTransformer: facebook-dpr-ctx_encoder-multiset-base
INFO:sentence_transformers.SentenceTransformer:Use pytorch device: cpu
INFO:sentence_transformers.SentenceTransformer:Load pretrained SentenceTransformer: facebook-dpr-ctx_encoder-multiset-base
INFO:sentence_transformers.SentenceTransformer:Use pytorch device: cpu
INFO:sentence_transformers.SentenceTransformer:Load pretrained SentenceTransformer: facebook-dpr-ctx_encoder-multiset-base
INFO:sentence_transformers.SentenceTransformer:Use pytorch device: cpu
INFO:chromadb.telemetry.posthog:Anonymized telemetry enabled. See https://docs.trychroma.com/telemetry for more information.
INFO:chromadb.telemetry.posthog:Anonymized telemetry enabled. See https://docs.trychroma.com/telemetry for more information.
INFO:sentence_transformers.SentenceTransformer:Load pretrained SentenceTransformer: facebook-dpr-ctx_encoder-multiset-base
INFO:sentence_transformers.SentenceTransformer:Use pytorch device: cpu
INFO:chromadb.telemetry.posthog:Anonymized telemetry enabled. See https://docs.trychroma.com/telemetry for more information.
INFO:openai:error_code=context_length_exceeded error_message="This model's maximum context length is 4097 tokens. However, your messages resulted in 7329 tokens. Please reduce the length of the messages." error_param=messages error_type=invalid_request_error message='OpenAI API error received' stream_error=False
INFO:sentence_transformers.SentenceTransformer:Load pretrained SentenceTransformer: facebook-dpr-ctx_encoder-multiset-base
INFO:sentence_transformers.SentenceTransformer:Use pytorch device: cpu
INFO:chromadb.telemetry.posthog:Anonymized telemetry enabled. See https://docs.trychroma.com/telemetry for more information.
INFO:chromadb.telemetry.posthog:Anonymized telemetry enabled. See https://docs.trychroma.com/telemetry for more information.
INFO:sentence_transformers.SentenceTransformer:Load pretrained SentenceTransformer: facebook-dpr-ctx_encoder-multiset-base
INFO:sentence_transformers.SentenceTransformer:Use pytorch device: cpu
INFO:chromadb.telemetry.posthog:Anonymized telemetry enabled. See https://docs.trychroma.com/telemetry for more information.
INFO:openai:error_code=context_length_exceeded error_message="This model's maximum context length is 4097 tokens. However, your messages resulted in 8543 tokens. Please reduce the length of the messages." error_param=messages error_type=invalid_request_error message='OpenAI API error received' stream_error=False
INFO:sentence_transformers.SentenceTransformer:Load pretrained SentenceTransformer: facebook-dpr-ctx_encoder-multiset-base
INFO:sentence_transformers.SentenceTransformer:Use pytorch device: cpu
INFO:chromadb.telemetry.posthog:Anonymized telemetry enabled. See https://docs.trychroma.com/telemetry for more information.
INFO:chromadb.telemetry.posthog:Anonymized telemetry enabled. See https://docs.trychroma.com/telemetry for more information.
INFO:sentence_transformers.SentenceTransformer:Load pretrained SentenceTransformer: facebook-dpr-ctx_encoder-multiset-base
INFO:sentence_transformers.SentenceTransformer:Use pytorch device: cpu
INFO:chromadb.telemetry.posthog:Anonymized telemetry enabled. See https://docs.trychroma.com/telemetry for more information.
INFO:chromadb.telemetry.posthog:Anonymized telemetry enabled. See https://docs.trychroma.com/telemetry for more information.
INFO:sentence_transformers.SentenceTransformer:Load pretrained SentenceTransformer: facebook-dpr-ctx_encoder-multiset-base
INFO:sentence_transformers.SentenceTransformer:Use pytorch device: cpu
INFO:chromadb.telemetry.posthog:Anonymized telemetry enabled. See https://docs.trychroma.com/telemetry for more information.
INFO:sentence_transformers.SentenceTransformer:Load pretrained SentenceTransformer: facebook-dpr-ctx_encoder-multiset-base
INFO:sentence_transformers.SentenceTransformer:Use pytorch device: cpu
INFO:chromadb.telemetry.posthog:Anonymized telemetry enabled. See https://docs.trychroma.com/telemetry for more information.
INFO:chromadb.telemetry.posthog:Anonymized telemetry enabled. See https://docs.trychroma.com/telemetry for more information.
INFO:sentence_transformers.SentenceTransformer:Load pretrained SentenceTransformer: facebook-dpr-ctx_encoder-multiset-base
INFO:sentence_transformers.SentenceTransformer:Use pytorch device: cpu
INFO:chromadb.telemetry.posthog:Anonymized telemetry enabled. See https://docs.trychroma.com/telemetry for more information.
INFO:sentence_transformers.SentenceTransformer:Load pretrained SentenceTransformer: facebook-dpr-ctx_encoder-multiset-base
INFO:sentence_transformers.SentenceTransformer:Use pytorch device: cpu
INFO:chromadb.telemetry.posthog:Anonymized telemetry enabled. See https://docs.trychroma.com/telemetry for more information.
INFO:chromadb.telemetry.posthog:Anonymized telemetry enabled. See https://docs.trychroma.com/telemetry for more information.
INFO:sentence_transformers.SentenceTransformer:Load pretrained SentenceTransformer: facebook-dpr-ctx_encoder-multiset-base
INFO:sentence_transformers.SentenceTransformer:Use pytorch device: cpu
INFO:chromadb.telemetry.posthog:Anonymized telemetry enabled. See https://docs.trychroma.com/telemetry for more information.
INFO:sentence_transformers.SentenceTransformer:Load pretrained SentenceTransformer: facebook-dpr-ctx_encoder-multiset-base
INFO:sentence_transformers.SentenceTransformer:Use pytorch device: cpu
INFO:chromadb.telemetry.posthog:Anonymized telemetry enabled. See https://docs.trychroma.com/telemetry for more information.
INFO:chromadb.telemetry.posthog:Anonymized telemetry enabled. See https://docs.trychroma.com/telemetry for more information.
INFO:sentence_transformers.SentenceTransformer:Load pretrained SentenceTransformer: facebook-dpr-ctx_encoder-multiset-base
INFO:sentence_transformers.SentenceTransformer:Use pytorch device: cpu
INFO:chromadb.telemetry.posthog:Anonymized telemetry enabled. See https://docs.trychroma.com/telemetry for more information.
INFO:openai:error_code=context_length_exceeded error_message="This model's maximum context length is 4097 tokens. However, your messages resulted in 5952 tokens. Please reduce the length of the messages." error_param=messages error_type=invalid_request_error message='OpenAI API error received' stream_error=False
INFO:sentence_transformers.SentenceTransformer:Load pretrained SentenceTransformer: facebook-dpr-ctx_encoder-multiset-base
INFO:sentence_transformers.SentenceTransformer:Use pytorch device: cpu
INFO:chromadb.telemetry.posthog:Anonymized telemetry enabled. See https://docs.trychroma.com/telemetry for more information.
WARNING:urllib3.connectionpool:Retrying (Retry(total=1, connect=None, read=None, redirect=None, status=None)) after connection broken by 'NewConnectionError('<urllib3.connection.HTTPSConnection object at 0x7ff13ad7e260>: Failed to establish a new connection: [Errno 61] Connection refused')': /v1/embeddings
WARNING:urllib3.connectionpool:Retrying (Retry(total=0, connect=None, read=None, redirect=None, status=None)) after connection broken by 'NewConnectionError('<urllib3.connection.HTTPSConnection object at 0x7ff13ad7da50>: Failed to establish a new connection: [Errno 61] Connection refused')': /v1/embeddings
WARNING:langchain.embeddings.openai:Retrying langchain.embeddings.openai.embed_with_retry.<locals>._embed_with_retry in 4.0 seconds as it raised APIConnectionError: Error communicating with OpenAI: HTTPSConnectionPool(host='api.openai.com', port=443): Max retries exceeded with url: /v1/embeddings (Caused by NewConnectionError('<urllib3.connection.HTTPSConnection object at 0x7ff13ad7e620>: Failed to establish a new connection: [Errno 61] Connection refused')).
INFO:backoff:Backing off send_request(...) for 0.6s (requests.exceptions.ConnectionError: HTTPSConnectionPool(host='app.posthog.com', port=443): Max retries exceeded with url: /batch/ (Caused by NewConnectionError('<urllib3.connection.HTTPSConnection object at 0x7ff13ad7ecb0>: Failed to establish a new connection: [Errno 61] Connection refused')))
INFO:backoff:Backing off send_request(...) for 0.4s (requests.exceptions.ConnectionError: HTTPSConnectionPool(host='app.posthog.com', port=443): Max retries exceeded with url: /batch/ (Caused by NewConnectionError('<urllib3.connection.HTTPSConnection object at 0x7ff14052bfa0>: Failed to establish a new connection: [Errno 61] Connection refused')))
INFO:backoff:Backing off send_request(...) for 1.7s (requests.exceptions.ConnectionError: HTTPSConnectionPool(host='app.posthog.com', port=443): Max retries exceeded with url: /batch/ (Caused by NewConnectionError('<urllib3.connection.HTTPSConnection object at 0x7ff14052bca0>: Failed to establish a new connection: [Errno 61] Connection refused')))
ERROR:backoff:Giving up send_request(...) after 4 tries (requests.exceptions.ConnectionError: HTTPSConnectionPool(host='app.posthog.com', port=443): Max retries exceeded with url: /batch/ (Caused by NewConnectionError('<urllib3.connection.HTTPSConnection object at 0x7ff14052b970>: Failed to establish a new connection: [Errno 61] Connection refused')))
WARNING:urllib3.connectionpool:Retrying (Retry(total=1, connect=None, read=None, redirect=None, status=None)) after connection broken by 'NewConnectionError('<urllib3.connection.HTTPSConnection object at 0x7ff13adb0370>: Failed to establish a new connection: [Errno 61] Connection refused')': /v1/embeddings
WARNING:urllib3.connectionpool:Retrying (Retry(total=0, connect=None, read=None, redirect=None, status=None)) after connection broken by 'NewConnectionError('<urllib3.connection.HTTPSConnection object at 0x7ff13ad7eb60>: Failed to establish a new connection: [Errno 61] Connection refused')': /v1/embeddings
WARNING:langchain.embeddings.openai:Retrying langchain.embeddings.openai.embed_with_retry.<locals>._embed_with_retry in 4.0 seconds as it raised APIConnectionError: Error communicating with OpenAI: HTTPSConnectionPool(host='api.openai.com', port=443): Max retries exceeded with url: /v1/embeddings (Caused by NewConnectionError('<urllib3.connection.HTTPSConnection object at 0x7ff13ad7efb0>: Failed to establish a new connection: [Errno 61] Connection refused')).
WARNING:urllib3.connectionpool:Retrying (Retry(total=1, connect=None, read=None, redirect=None, status=None)) after connection broken by 'NewConnectionError('<urllib3.connection.HTTPSConnection object at 0x7ff13ad7d690>: Failed to establish a new connection: [Errno 61] Connection refused')': /v1/embeddings
WARNING:urllib3.connectionpool:Retrying (Retry(total=0, connect=None, read=None, redirect=None, status=None)) after connection broken by 'NewConnectionError('<urllib3.connection.HTTPSConnection object at 0x7ff13ad7e170>: Failed to establish a new connection: [Errno 61] Connection refused')': /v1/embeddings
WARNING:langchain.embeddings.openai:Retrying langchain.embeddings.openai.embed_with_retry.<locals>._embed_with_retry in 4.0 seconds as it raised APIConnectionError: Error communicating with OpenAI: HTTPSConnectionPool(host='api.openai.com', port=443): Max retries exceeded with url: /v1/embeddings (Caused by NewConnectionError('<urllib3.connection.HTTPSConnection object at 0x7ff13ad7caf0>: Failed to establish a new connection: [Errno 61] Connection refused')).
WARNING:urllib3.connectionpool:Retrying (Retry(total=1, connect=None, read=None, redirect=None, status=None)) after connection broken by 'NewConnectionError('<urllib3.connection.HTTPSConnection object at 0x7ff14052b640>: Failed to establish a new connection: [Errno 61] Connection refused')': /v1/embeddings
WARNING:urllib3.connectionpool:Retrying (Retry(total=0, connect=None, read=None, redirect=None, status=None)) after connection broken by 'NewConnectionError('<urllib3.connection.HTTPSConnection object at 0x7ff14052b8b0>: Failed to establish a new connection: [Errno 61] Connection refused')': /v1/embeddings
WARNING:langchain.embeddings.openai:Retrying langchain.embeddings.openai.embed_with_retry.<locals>._embed_with_retry in 8.0 seconds as it raised APIConnectionError: Error communicating with OpenAI: HTTPSConnectionPool(host='api.openai.com', port=443): Max retries exceeded with url: /v1/embeddings (Caused by NewConnectionError('<urllib3.connection.HTTPSConnection object at 0x7ff14052bc10>: Failed to establish a new connection: [Errno 61] Connection refused')).
WARNING:urllib3.connectionpool:Retrying (Retry(total=1, connect=None, read=None, redirect=None, status=None)) after connection broken by 'NewConnectionError('<urllib3.connection.HTTPSConnection object at 0x7ff14052bfd0>: Failed to establish a new connection: [Errno 61] Connection refused')': /v1/embeddings
WARNING:urllib3.connectionpool:Retrying (Retry(total=0, connect=None, read=None, redirect=None, status=None)) after connection broken by 'NewConnectionError('<urllib3.connection.HTTPSConnection object at 0x7ff14052b1f0>: Failed to establish a new connection: [Errno 61] Connection refused')': /v1/embeddings
WARNING:langchain.embeddings.openai:Retrying langchain.embeddings.openai.embed_with_retry.<locals>._embed_with_retry in 10.0 seconds as it raised APIConnectionError: Error communicating with OpenAI: HTTPSConnectionPool(host='api.openai.com', port=443): Max retries exceeded with url: /v1/embeddings (Caused by NewConnectionError('<urllib3.connection.HTTPSConnection object at 0x7ff14052b040>: Failed to establish a new connection: [Errno 61] Connection refused')).
WARNING:urllib3.connectionpool:Retrying (Retry(total=1, connect=None, read=None, redirect=None, status=None)) after connection broken by 'NewConnectionError('<urllib3.connection.HTTPSConnection object at 0x7ff14052ab90>: Failed to establish a new connection: [Errno 61] Connection refused')': /v1/embeddings
WARNING:urllib3.connectionpool:Retrying (Retry(total=0, connect=None, read=None, redirect=None, status=None)) after connection broken by 'NewConnectionError('<urllib3.connection.HTTPSConnection object at 0x7ff14052a950>: Failed to establish a new connection: [Errno 61] Connection refused')': /v1/embeddings
INFO:sentence_transformers.SentenceTransformer:Load pretrained SentenceTransformer: facebook-dpr-ctx_encoder-multiset-base
INFO:sentence_transformers.SentenceTransformer:Use pytorch device: cpu
INFO:chromadb.telemetry.posthog:Anonymized telemetry enabled. See https://docs.trychroma.com/telemetry for more information.
WARNING:urllib3.connectionpool:Retrying (Retry(total=1, connect=None, read=None, redirect=None, status=None)) after connection broken by 'NewConnectionError('<urllib3.connection.HTTPSConnection object at 0x7fa529155c90>: Failed to establish a new connection: [Errno 61] Connection refused')': /v1/embeddings
WARNING:urllib3.connectionpool:Retrying (Retry(total=0, connect=None, read=None, redirect=None, status=None)) after connection broken by 'NewConnectionError('<urllib3.connection.HTTPSConnection object at 0x7fa529157730>: Failed to establish a new connection: [Errno 61] Connection refused')': /v1/embeddings
WARNING:langchain.embeddings.openai:Retrying langchain.embeddings.openai.embed_with_retry.<locals>._embed_with_retry in 4.0 seconds as it raised APIConnectionError: Error communicating with OpenAI: HTTPSConnectionPool(host='api.openai.com', port=443): Max retries exceeded with url: /v1/embeddings (Caused by NewConnectionError('<urllib3.connection.HTTPSConnection object at 0x7fa5291558d0>: Failed to establish a new connection: [Errno 61] Connection refused')).
INFO:backoff:Backing off send_request(...) for 0.5s (requests.exceptions.ConnectionError: HTTPSConnectionPool(host='app.posthog.com', port=443): Max retries exceeded with url: /batch/ (Caused by NewConnectionError('<urllib3.connection.HTTPSConnection object at 0x7fa529155240>: Failed to establish a new connection: [Errno 61] Connection refused')))
INFO:backoff:Backing off send_request(...) for 0.4s (requests.exceptions.ConnectionError: HTTPSConnectionPool(host='app.posthog.com', port=443): Max retries exceeded with url: /batch/ (Caused by NewConnectionError('<urllib3.connection.HTTPSConnection object at 0x7fa52f25ffa0>: Failed to establish a new connection: [Errno 61] Connection refused')))
INFO:backoff:Backing off send_request(...) for 0.7s (requests.exceptions.ConnectionError: HTTPSConnectionPool(host='app.posthog.com', port=443): Max retries exceeded with url: /batch/ (Caused by NewConnectionError('<urllib3.connection.HTTPSConnection object at 0x7fa52f25fca0>: Failed to establish a new connection: [Errno 61] Connection refused')))
ERROR:backoff:Giving up send_request(...) after 4 tries (requests.exceptions.ConnectionError: HTTPSConnectionPool(host='app.posthog.com', port=443): Max retries exceeded with url: /batch/ (Caused by NewConnectionError('<urllib3.connection.HTTPSConnection object at 0x7fa52f25f970>: Failed to establish a new connection: [Errno 61] Connection refused')))
WARNING:urllib3.connectionpool:Retrying (Retry(total=1, connect=None, read=None, redirect=None, status=None)) after connection broken by 'NewConnectionError('<urllib3.connection.HTTPSConnection object at 0x7fa529184490>: Failed to establish a new connection: [Errno 61] Connection refused')': /v1/embeddings
WARNING:urllib3.connectionpool:Retrying (Retry(total=0, connect=None, read=None, redirect=None, status=None)) after connection broken by 'NewConnectionError('<urllib3.connection.HTTPSConnection object at 0x7fa529155540>: Failed to establish a new connection: [Errno 61] Connection refused')': /v1/embeddings
WARNING:langchain.embeddings.openai:Retrying langchain.embeddings.openai.embed_with_retry.<locals>._embed_with_retry in 4.0 seconds as it raised APIConnectionError: Error communicating with OpenAI: HTTPSConnectionPool(host='api.openai.com', port=443): Max retries exceeded with url: /v1/embeddings (Caused by NewConnectionError('<urllib3.connection.HTTPSConnection object at 0x7fa529154580>: Failed to establish a new connection: [Errno 61] Connection refused')).
WARNING:urllib3.connectionpool:Retrying (Retry(total=1, connect=None, read=None, redirect=None, status=None)) after connection broken by 'NewConnectionError('<urllib3.connection.HTTPSConnection object at 0x7fa529156860>: Failed to establish a new connection: [Errno 61] Connection refused')': /v1/embeddings
WARNING:urllib3.connectionpool:Retrying (Retry(total=0, connect=None, read=None, redirect=None, status=None)) after connection broken by 'NewConnectionError('<urllib3.connection.HTTPSConnection object at 0x7fa529155d80>: Failed to establish a new connection: [Errno 61] Connection refused')': /v1/embeddings
WARNING:langchain.embeddings.openai:Retrying langchain.embeddings.openai.embed_with_retry.<locals>._embed_with_retry in 4.0 seconds as it raised APIConnectionError: Error communicating with OpenAI: HTTPSConnectionPool(host='api.openai.com', port=443): Max retries exceeded with url: /v1/embeddings (Caused by NewConnectionError('<urllib3.connection.HTTPSConnection object at 0x7fa529157400>: Failed to establish a new connection: [Errno 61] Connection refused')).
WARNING:urllib3.connectionpool:Retrying (Retry(total=1, connect=None, read=None, redirect=None, status=None)) after connection broken by 'NewConnectionError('<urllib3.connection.HTTPSConnection object at 0x7fa52f25f640>: Failed to establish a new connection: [Errno 61] Connection refused')': /v1/embeddings
WARNING:urllib3.connectionpool:Retrying (Retry(total=0, connect=None, read=None, redirect=None, status=None)) after connection broken by 'NewConnectionError('<urllib3.connection.HTTPSConnection object at 0x7fa52f25f8b0>: Failed to establish a new connection: [Errno 61] Connection refused')': /v1/embeddings
WARNING:langchain.embeddings.openai:Retrying langchain.embeddings.openai.embed_with_retry.<locals>._embed_with_retry in 8.0 seconds as it raised APIConnectionError: Error communicating with OpenAI: HTTPSConnectionPool(host='api.openai.com', port=443): Max retries exceeded with url: /v1/embeddings (Caused by NewConnectionError('<urllib3.connection.HTTPSConnection object at 0x7fa52f25fc10>: Failed to establish a new connection: [Errno 61] Connection refused')).
WARNING:urllib3.connectionpool:Retrying (Retry(total=1, connect=None, read=None, redirect=None, status=None)) after connection broken by 'NewConnectionError('<urllib3.connection.HTTPSConnection object at 0x7fa52f25ffd0>: Failed to establish a new connection: [Errno 61] Connection refused')': /v1/embeddings
WARNING:urllib3.connectionpool:Retrying (Retry(total=0, connect=None, read=None, redirect=None, status=None)) after connection broken by 'NewConnectionError('<urllib3.connection.HTTPSConnection object at 0x7fa52f25f1f0>: Failed to establish a new connection: [Errno 61] Connection refused')': /v1/embeddings
WARNING:langchain.embeddings.openai:Retrying langchain.embeddings.openai.embed_with_retry.<locals>._embed_with_retry in 10.0 seconds as it raised APIConnectionError: Error communicating with OpenAI: HTTPSConnectionPool(host='api.openai.com', port=443): Max retries exceeded with url: /v1/embeddings (Caused by NewConnectionError('<urllib3.connection.HTTPSConnection object at 0x7fa52f25f040>: Failed to establish a new connection: [Errno 61] Connection refused')).
INFO:sentence_transformers.SentenceTransformer:Load pretrained SentenceTransformer: facebook-dpr-ctx_encoder-multiset-base
INFO:sentence_transformers.SentenceTransformer:Use pytorch device: cpu
INFO:chromadb.telemetry.posthog:Anonymized telemetry enabled. See https://docs.trychroma.com/telemetry for more information.
WARNING:urllib3.connectionpool:Retrying (Retry(total=1, connect=None, read=None, redirect=None, status=None)) after connection broken by 'NewConnectionError('<urllib3.connection.HTTPSConnection object at 0x7ff28801e860>: Failed to establish a new connection: [Errno 61] Connection refused')': /v1/embeddings
WARNING:urllib3.connectionpool:Retrying (Retry(total=0, connect=None, read=None, redirect=None, status=None)) after connection broken by 'NewConnectionError('<urllib3.connection.HTTPSConnection object at 0x7ff28801de10>: Failed to establish a new connection: [Errno 61] Connection refused')': /v1/embeddings
WARNING:langchain.embeddings.openai:Retrying langchain.embeddings.openai.embed_with_retry.<locals>._embed_with_retry in 4.0 seconds as it raised APIConnectionError: Error communicating with OpenAI: HTTPSConnectionPool(host='api.openai.com', port=443): Max retries exceeded with url: /v1/embeddings (Caused by NewConnectionError('<urllib3.connection.HTTPSConnection object at 0x7ff28801ec20>: Failed to establish a new connection: [Errno 61] Connection refused')).
INFO:backoff:Backing off send_request(...) for 0.9s (requests.exceptions.ConnectionError: HTTPSConnectionPool(host='app.posthog.com', port=443): Max retries exceeded with url: /batch/ (Caused by NewConnectionError('<urllib3.connection.HTTPSConnection object at 0x7ff28801f2b0>: Failed to establish a new connection: [Errno 61] Connection refused')))
INFO:backoff:Backing off send_request(...) for 0.1s (requests.exceptions.ConnectionError: HTTPSConnectionPool(host='app.posthog.com', port=443): Max retries exceeded with url: /batch/ (Caused by NewConnectionError('<urllib3.connection.HTTPSConnection object at 0x7ff2884ebfa0>: Failed to establish a new connection: [Errno 61] Connection refused')))
INFO:backoff:Backing off send_request(...) for 1.5s (requests.exceptions.ConnectionError: HTTPSConnectionPool(host='app.posthog.com', port=443): Max retries exceeded with url: /batch/ (Caused by NewConnectionError('<urllib3.connection.HTTPSConnection object at 0x7ff2884ebca0>: Failed to establish a new connection: [Errno 61] Connection refused')))
ERROR:backoff:Giving up send_request(...) after 4 tries (requests.exceptions.ConnectionError: HTTPSConnectionPool(host='app.posthog.com', port=443): Max retries exceeded with url: /batch/ (Caused by NewConnectionError('<urllib3.connection.HTTPSConnection object at 0x7ff2884eb970>: Failed to establish a new connection: [Errno 61] Connection refused')))
WARNING:urllib3.connectionpool:Retrying (Retry(total=1, connect=None, read=None, redirect=None, status=None)) after connection broken by 'NewConnectionError('<urllib3.connection.HTTPSConnection object at 0x7ff28805c460>: Failed to establish a new connection: [Errno 61] Connection refused')': /v1/embeddings
WARNING:urllib3.connectionpool:Retrying (Retry(total=0, connect=None, read=None, redirect=None, status=None)) after connection broken by 'NewConnectionError('<urllib3.connection.HTTPSConnection object at 0x7ff28801f040>: Failed to establish a new connection: [Errno 61] Connection refused')': /v1/embeddings
WARNING:langchain.embeddings.openai:Retrying langchain.embeddings.openai.embed_with_retry.<locals>._embed_with_retry in 4.0 seconds as it raised APIConnectionError: Error communicating with OpenAI: HTTPSConnectionPool(host='api.openai.com', port=443): Max retries exceeded with url: /v1/embeddings (Caused by NewConnectionError('<urllib3.connection.HTTPSConnection object at 0x7ff28801f5e0>: Failed to establish a new connection: [Errno 61] Connection refused')).
WARNING:urllib3.connectionpool:Retrying (Retry(total=1, connect=None, read=None, redirect=None, status=None)) after connection broken by 'NewConnectionError('<urllib3.connection.HTTPSConnection object at 0x7ff28801dc90>: Failed to establish a new connection: [Errno 61] Connection refused')': /v1/embeddings
WARNING:urllib3.connectionpool:Retrying (Retry(total=0, connect=None, read=None, redirect=None, status=None)) after connection broken by 'NewConnectionError('<urllib3.connection.HTTPSConnection object at 0x7ff28801e770>: Failed to establish a new connection: [Errno 61] Connection refused')': /v1/embeddings
WARNING:langchain.embeddings.openai:Retrying langchain.embeddings.openai.embed_with_retry.<locals>._embed_with_retry in 4.0 seconds as it raised APIConnectionError: Error communicating with OpenAI: HTTPSConnectionPool(host='api.openai.com', port=443): Max retries exceeded with url: /v1/embeddings (Caused by NewConnectionError('<urllib3.connection.HTTPSConnection object at 0x7ff28801d1e0>: Failed to establish a new connection: [Errno 61] Connection refused')).
WARNING:urllib3.connectionpool:Retrying (Retry(total=1, connect=None, read=None, redirect=None, status=None)) after connection broken by 'NewConnectionError('<urllib3.connection.HTTPSConnection object at 0x7ff2884eb640>: Failed to establish a new connection: [Errno 61] Connection refused')': /v1/embeddings
WARNING:urllib3.connectionpool:Retrying (Retry(total=0, connect=None, read=None, redirect=None, status=None)) after connection broken by 'NewConnectionError('<urllib3.connection.HTTPSConnection object at 0x7ff2884eb8b0>: Failed to establish a new connection: [Errno 61] Connection refused')': /v1/embeddings
WARNING:langchain.embeddings.openai:Retrying langchain.embeddings.openai.embed_with_retry.<locals>._embed_with_retry in 8.0 seconds as it raised APIConnectionError: Error communicating with OpenAI: HTTPSConnectionPool(host='api.openai.com', port=443): Max retries exceeded with url: /v1/embeddings (Caused by NewConnectionError('<urllib3.connection.HTTPSConnection object at 0x7ff2884ebc10>: Failed to establish a new connection: [Errno 61] Connection refused')).
WARNING:urllib3.connectionpool:Retrying (Retry(total=1, connect=None, read=None, redirect=None, status=None)) after connection broken by 'NewConnectionError('<urllib3.connection.HTTPSConnection object at 0x7ff2884ebfd0>: Failed to establish a new connection: [Errno 61] Connection refused')': /v1/embeddings
WARNING:urllib3.connectionpool:Retrying (Retry(total=0, connect=None, read=None, redirect=None, status=None)) after connection broken by 'NewConnectionError('<urllib3.connection.HTTPSConnection object at 0x7ff2884eb1f0>: Failed to establish a new connection: [Errno 61] Connection refused')': /v1/embeddings
WARNING:langchain.embeddings.openai:Retrying langchain.embeddings.openai.embed_with_retry.<locals>._embed_with_retry in 10.0 seconds as it raised APIConnectionError: Error communicating with OpenAI: HTTPSConnectionPool(host='api.openai.com', port=443): Max retries exceeded with url: /v1/embeddings (Caused by NewConnectionError('<urllib3.connection.HTTPSConnection object at 0x7ff2884eb040>: Failed to establish a new connection: [Errno 61] Connection refused')).
WARNING:urllib3.connectionpool:Retrying (Retry(total=1, connect=None, read=None, redirect=None, status=None)) after connection broken by 'NewConnectionError('<urllib3.connection.HTTPSConnection object at 0x7ff2884eab90>: Failed to establish a new connection: [Errno 61] Connection refused')': /v1/embeddings
WARNING:urllib3.connectionpool:Retrying (Retry(total=0, connect=None, read=None, redirect=None, status=None)) after connection broken by 'NewConnectionError('<urllib3.connection.HTTPSConnection object at 0x7ff2884ea950>: Failed to establish a new connection: [Errno 61] Connection refused')': /v1/embeddings
INFO:sentence_transformers.SentenceTransformer:Load pretrained SentenceTransformer: facebook-dpr-ctx_encoder-multiset-base
INFO:sentence_transformers.SentenceTransformer:Use pytorch device: cpu
INFO:chromadb.telemetry.posthog:Anonymized telemetry enabled. See https://docs.trychroma.com/telemetry for more information.
INFO:chromadb.telemetry.posthog:Anonymized telemetry enabled. See https://docs.trychroma.com/telemetry for more information.
INFO:sentence_transformers.SentenceTransformer:Load pretrained SentenceTransformer: facebook-dpr-ctx_encoder-multiset-base
INFO:sentence_transformers.SentenceTransformer:Use pytorch device: cpu
INFO:chromadb.telemetry.posthog:Anonymized telemetry enabled. See https://docs.trychroma.com/telemetry for more information.
INFO:sentence_transformers.SentenceTransformer:Load pretrained SentenceTransformer: facebook-dpr-ctx_encoder-multiset-base
INFO:sentence_transformers.SentenceTransformer:Use pytorch device: cpu
INFO:chromadb.telemetry.posthog:Anonymized telemetry enabled. See https://docs.trychroma.com/telemetry for more information.
INFO:chromadb.telemetry.posthog:Anonymized telemetry enabled. See https://docs.trychroma.com/telemetry for more information.
INFO:sentence_transformers.SentenceTransformer:Load pretrained SentenceTransformer: facebook-dpr-ctx_encoder-multiset-base
INFO:sentence_transformers.SentenceTransformer:Use pytorch device: cpu
INFO:chromadb.telemetry.posthog:Anonymized telemetry enabled. See https://docs.trychroma.com/telemetry for more information.
INFO:openai:error_code=context_length_exceeded error_message="This model's maximum context length is 4097 tokens. However, your messages resulted in 5963 tokens. Please reduce the length of the messages." error_param=messages error_type=invalid_request_error message='OpenAI API error received' stream_error=False
INFO:sentence_transformers.SentenceTransformer:Load pretrained SentenceTransformer: facebook-dpr-ctx_encoder-multiset-base
INFO:sentence_transformers.SentenceTransformer:Use pytorch device: cpu
INFO:chromadb.telemetry.posthog:Anonymized telemetry enabled. See https://docs.trychroma.com/telemetry for more information.
INFO:chromadb.telemetry.posthog:Anonymized telemetry enabled. See https://docs.trychroma.com/telemetry for more information.
INFO:sentence_transformers.SentenceTransformer:Load pretrained SentenceTransformer: facebook-dpr-ctx_encoder-multiset-base
INFO:sentence_transformers.SentenceTransformer:Use pytorch device: cpu
INFO:chromadb.telemetry.posthog:Anonymized telemetry enabled. See https://docs.trychroma.com/telemetry for more information.
INFO:chromadb.telemetry.posthog:Anonymized telemetry enabled. See https://docs.trychroma.com/telemetry for more information.
INFO:sentence_transformers.SentenceTransformer:Load pretrained SentenceTransformer: facebook-dpr-ctx_encoder-multiset-base
INFO:sentence_transformers.SentenceTransformer:Use pytorch device: cpu
INFO:root:agent_snd
INFO:root:agent_snd
INFO:root:agent_snd
INFO:root:agent_snd
